<mujoco><asset><texture name="checkered" type="2d" builtin="checker" rgb1="0.2 0.3 0.4" rgb2="0.9 0.9 0.9" width="512" height="512" /><material name="MatCheckered" texture="checkered" reflectance="0.5" /><material name="MatPlane" reflectance="0.5" shininess="1" specular="1" /><material name="red" rgba="1 0 0 1" /><material name="green" rgba="0 1 0 1" /><material name="blue" rgba="0 0 1 1" /><material name="yellow" rgba="1 1 0 1" /><material name="purple" rgba="0.5 0 0.5 1" /><material name="orange" rgba="1 0.5 0 1" /><material name="pink" rgba="1 0.7 0.7 1" /><material name="grey" rgba="0.5 0.5 0.5 1" /><material name="brown" rgba="0.6 0.3 0 1" /></asset><worldbody><geom name="floor" type="plane" size="10 10 0.1" pos="0 0 0" material="MatCheckered" /><body name="torso_0" pos="-6.5 -6.5 0.75"><geom name="torso_geom_torso_0" type="box" size="0.38977917209483026 0.11837299173934657 0.06303994047526805" pos="0 0 0" contype="1" conaffinity="1" material="red" /><joint name="torso_0_root" type="free" armature="0" damping="0" limited="false" /><site name="torso_0_site" pos="0 0 0" type="sphere" size="0.01" /><body name="leg_0_1" pos="0 -0.05918649586967328 0"><geom name="leg_0_1_upper_geom" type="capsule" fromto="0.0 0.0 0.0 0.15580092082919422 0.0 0.0" size="0.04" /><joint name="leg_0_1_hip_joint" type="ball" damping="2.0" /><body name="leg_0_1_lower" pos="0.15580092082919422 0.0 0.0"><geom name="leg_0_1_lower_geom" type="capsule" fromto="0.15580092082919422 0.0 0.0 0.3525411629149744 0.0 0.0" size="0.04" /><joint name="leg_0_1_knee_joint" type="hinge" axis="0 1 0" range="-90 90" damping="4.0" limited="true" /><body name="leg_0_1_foot" pos="0.3525411629149744 0.0 0.0"><geom name="leg_0_1_foot_geom" type="cylinder" fromto="0.3525411629149744 0.0 0.0 0.5271803761408339 0.0 0.0" size="0.04" /><joint name="leg_0_1_ankle_joint" type="ball" damping="6.0" /></body></body></body><body name="leg_0_2" pos="-0.19488958604741513 0 0"><geom name="leg_0_2_upper_geom" type="capsule" fromto="0.0 0.0 0.0 0.19550426595964226 0.0 0.0" size="0.04" /><joint name="leg_0_2_hip_joint" type="ball" damping="2.0" /><body name="leg_0_2_lower" pos="0.19550426595964226 0.0 0.0"><geom name="leg_0_2_lower_geom" type="capsule" fromto="0.19550426595964226 0.0 0.0 0.3746678666734952 0.0 0.0" size="0.04" /><joint name="leg_0_2_knee_joint" type="hinge" axis="0 1 0" range="-90 90" damping="4.0" limited="true" /><body name="leg_0_2_foot" pos="0.3746678666734952 0.0 0.0"><geom name="leg_0_2_foot_geom" type="cylinder" fromto="0.3746678666734952 0.0 0.0 0.5734682526379768 0.0 0.0" size="0.04" /><joint name="leg_0_2_ankle_joint" type="ball" damping="6.0" /></body></body></body></body><geom name="flag_0" type="box" size="0.05 0.05 0.5" pos="-7.415569115769876 -6.097839342739288 0" material="red" contype="1" conaffinity="1" /><body name="torso_1" pos="0 -6.5 0.75"><geom name="torso_geom_torso_1" type="box" size="0.3595059277440542 0.13669017664106098 0.0722544570371474" pos="0 0 0" contype="1" conaffinity="2" material="green" /><joint name="torso_1_root" type="free" armature="0" damping="0" limited="false" /><site name="torso_1_site" pos="0 0 0" type="sphere" size="0.01" /><body name="leg_1_1" pos="0.1797529638720271 0 0"><geom name="leg_1_1_upper_geom" type="capsule" fromto="0.0 0.0 0.0 0.14541785568840465 0.0 0.0" size="0.04" /><joint name="leg_1_1_hip_joint" type="ball" damping="2.0" /><body name="leg_1_1_lower" pos="0.14541785568840465 0.0 0.0"><geom name="leg_1_1_lower_geom" type="capsule" fromto="0.14541785568840465 0.0 0.0 0.2794063348507609 0.0 0.0" size="0.04" /><joint name="leg_1_1_knee_joint" type="hinge" axis="0 1 0" range="-90 90" damping="4.0" limited="true" /><body name="leg_1_1_foot" pos="0.2794063348507609 0.0 0.0"><geom name="leg_1_1_foot_geom" type="cylinder" fromto="0.2794063348507609 0.0 0.0 0.4219291531372916 0.0 0.0" size="0.04" /><joint name="leg_1_1_ankle_joint" type="ball" damping="6.0" /></body></body></body></body><geom name="flag_1" type="box" size="0.05 0.05 0.5" pos="-0.8297729907124739 -7.058101051677989 0" material="green" contype="1" conaffinity="2" /><body name="torso_2" pos="6.5 -6.5 0.75"><geom name="torso_geom_torso_2" type="box" size="0.3276940643963847 0.17483888676820175 0.08180314800271804" pos="0 0 0" contype="1" conaffinity="3" material="blue" /><joint name="torso_2_root" type="free" armature="0" damping="0" limited="false" /><site name="torso_2_site" pos="0 0 0" type="sphere" size="0.01" /><body name="leg_2_1" pos="0 0.08741944338410088 0"><geom name="leg_2_1_upper_geom" type="capsule" fromto="0.0 0.0 0.0 0.12167524503981537 0.0 0.0" size="0.04" /><joint name="leg_2_1_hip_joint" type="ball" damping="2.0" /><body name="leg_2_1_lower" pos="0.12167524503981537 0.0 0.0"><geom name="leg_2_1_lower_geom" type="capsule" fromto="0.12167524503981537 0.0 0.0 0.28360757934907427 0.0 0.0" size="0.04" /><joint name="leg_2_1_knee_joint" type="hinge" axis="0 1 0" range="-90 90" damping="4.0" limited="true" /><body name="leg_2_1_foot" pos="0.28360757934907427 0.0 0.0"><geom name="leg_2_1_foot_geom" type="cylinder" fromto="0.28360757934907427 0.0 0.0 0.4437860476573303 0.0 0.0" size="0.04" /><joint name="leg_2_1_ankle_joint" type="ball" damping="6.0" /></body></body></body></body><geom name="flag_2" type="box" size="0.05 0.05 0.5" pos="6.286667434210274 -5.523020360307559 0" material="blue" contype="1" conaffinity="3" /><body name="torso_3" pos="-6.5 0 0.75"><geom name="torso_geom_torso_3" type="box" size="0.3706874652875619 0.14170889901534514 0.06791997037859068" pos="0 0 0" contype="1" conaffinity="4" material="yellow" /><joint name="torso_3_root" type="free" armature="0" damping="0" limited="false" /><site name="torso_3_site" pos="0 0 0" type="sphere" size="0.01" /><body name="leg_3_1" pos="-0.18534373264378096 0 0"><geom name="leg_3_1_upper_geom" type="capsule" fromto="0.0 0.0 0.0 0.15286878442211235 0.0 0.0" size="0.04" /><joint name="leg_3_1_hip_joint" type="ball" damping="2.0" /><body name="leg_3_1_lower" pos="0.15286878442211235 0.0 0.0"><geom name="leg_3_1_lower_geom" type="capsule" fromto="0.15286878442211235 0.0 0.0 0.30211581336512133 0.0 0.0" size="0.04" /><joint name="leg_3_1_knee_joint" type="hinge" axis="0 1 0" range="-90 90" damping="4.0" limited="true" /><body name="leg_3_1_foot" pos="0.30211581336512133 0.0 0.0"><geom name="leg_3_1_foot_geom" type="cylinder" fromto="0.30211581336512133 0.0 0.0 0.48188306886805443 0.0 0.0" size="0.04" /><joint name="leg_3_1_ankle_joint" type="ball" damping="6.0" /></body></body></body><body name="leg_3_2" pos="0.18534373264378096 0 0"><geom name="leg_3_2_upper_geom" type="capsule" fromto="0.0 0.0 0.0 0.16479146454953478 0.0 0.0" size="0.04" /><joint name="leg_3_2_hip_joint" type="ball" damping="2.0" /><body name="leg_3_2_lower" pos="0.16479146454953478 0.0 0.0"><geom name="leg_3_2_lower_geom" type="capsule" fromto="0.16479146454953478 0.0 0.0 0.2757688301821561 0.0 0.0" size="0.04" /><joint name="leg_3_2_knee_joint" type="hinge" axis="0 1 0" range="-90 90" damping="4.0" limited="true" /><body name="leg_3_2_foot" pos="0.2757688301821561 0.0 0.0"><geom name="leg_3_2_foot_geom" type="cylinder" fromto="0.2757688301821561 0.0 0.0 0.43359295489346866 0.0 0.0" size="0.04" /><joint name="leg_3_2_ankle_joint" type="ball" damping="6.0" /></body></body></body></body><geom name="flag_3" type="box" size="0.05 0.05 0.5" pos="-5.600391069416982 0.43669643004640957 0" material="yellow" contype="1" conaffinity="4" /><body name="torso_4" pos="0 0 0.75"><geom name="torso_geom_torso_4" type="box" size="0.2555103199506398 0.1183244454409254 0.05905930397655051" pos="0 0 0" contype="1" conaffinity="5" material="purple" /><joint name="torso_4_root" type="free" armature="0" damping="0" limited="false" /><site name="torso_4_site" pos="0 0 0" type="sphere" size="0.01" /><body name="leg_4_1" pos="0 0.0591622227204627 0"><geom name="leg_4_1_upper_geom" type="capsule" fromto="0.0 0.0 0.0 0.15697624345725572 0.0 0.0" size="0.04" /><joint name="leg_4_1_hip_joint" type="ball" damping="2.0" /><body name="leg_4_1_lower" pos="0.15697624345725572 0.0 0.0"><geom name="leg_4_1_lower_geom" type="capsule" fromto="0.15697624345725572 0.0 0.0 0.28357684170984965 0.0 0.0" size="0.04" /><joint name="leg_4_1_knee_joint" type="hinge" axis="0 1 0" range="-90 90" damping="4.0" limited="true" /><body name="leg_4_1_foot" pos="0.28357684170984965 0.0 0.0"><geom name="leg_4_1_foot_geom" type="cylinder" fromto="0.28357684170984965 0.0 0.0 0.46720086429618757 0.0 0.0" size="0.04" /><joint name="leg_4_1_ankle_joint" type="ball" damping="6.0" /></body></body></body><body name="leg_4_2" pos="0 0.0591622227204627 0"><geom name="leg_4_2_upper_geom" type="capsule" fromto="0.0 0.0 0.0 0.17247003912202014 0.0 0.0" size="0.04" /><joint name="leg_4_2_hip_joint" type="ball" damping="2.0" /><body name="leg_4_2_lower" pos="0.17247003912202014 0.0 0.0"><geom name="leg_4_2_lower_geom" type="capsule" fromto="0.17247003912202014 0.0 0.0 0.2922859502996567 0.0 0.0" size="0.04" /><joint name="leg_4_2_knee_joint" type="hinge" axis="0 1 0" range="-90 90" damping="4.0" limited="true" /><body name="leg_4_2_foot" pos="0.2922859502996567 0.0 0.0"><geom name="leg_4_2_foot_geom" type="cylinder" fromto="0.2922859502996567 0.0 0.0 0.4826527731295615 0.0 0.0" size="0.04" /><joint name="leg_4_2_ankle_joint" type="ball" damping="6.0" /></body></body></body></body><geom name="flag_4" type="box" size="0.05 0.05 0.5" pos="-0.18306843089837688 0.9831001727232105 0" material="purple" contype="1" conaffinity="5" /><body name="torso_5" pos="6.5 0 0.75"><geom name="torso_geom_torso_5" type="box" size="0.23434916741056844 0.1518331281720993 0.05957853067390392" pos="0 0 0" contype="1" conaffinity="6" material="orange" /><joint name="torso_5_root" type="free" armature="0" damping="0" limited="false" /><site name="torso_5_site" pos="0 0 0" type="sphere" size="0.01" /><body name="leg_5_1" pos="0 -0.07591656408604965 0"><geom name="leg_5_1_upper_geom" type="capsule" fromto="0.0 0.0 0.0 0.16256595891093528 0.0 0.0" size="0.04" /><joint name="leg_5_1_hip_joint" type="ball" damping="2.0" /><body name="leg_5_1_lower" pos="0.16256595891093528 0.0 0.0"><geom name="leg_5_1_lower_geom" type="capsule" fromto="0.16256595891093528 0.0 0.0 0.32451830990402164 0.0 0.0" size="0.04" /><joint name="leg_5_1_knee_joint" type="hinge" axis="0 1 0" range="-90 90" damping="4.0" limited="true" /><body name="leg_5_1_foot" pos="0.32451830990402164 0.0 0.0"><geom name="leg_5_1_foot_geom" type="cylinder" fromto="0.32451830990402164 0.0 0.0 0.4819340858219256 0.0 0.0" size="0.04" /><joint name="leg_5_1_ankle_joint" type="ball" damping="6.0" /></body></body></body></body><geom name="flag_5" type="box" size="0.05 0.05 0.5" pos="7.325702263971502 -0.5641061702129628 0" material="orange" contype="1" conaffinity="6" /><body name="torso_6" pos="-6.5 6.5 0.75"><geom name="torso_geom_torso_6" type="box" size="0.253594813197969 0.11036591402111404 0.06417458671037023" pos="0 0 0" contype="1" conaffinity="7" material="pink" /><joint name="torso_6_root" type="free" armature="0" damping="0" limited="false" /><site name="torso_6_site" pos="0 0 0" type="sphere" size="0.01" /><body name="leg_6_1" pos="0.1267974065989845 0 0"><geom name="leg_6_1_upper_geom" type="capsule" fromto="0.0 0.0 0.0 0.19675330240875655 0.0 0.0" size="0.04" /><joint name="leg_6_1_hip_joint" type="ball" damping="2.0" /><body name="leg_6_1_lower" pos="0.19675330240875655 0.0 0.0"><geom name="leg_6_1_lower_geom" type="capsule" fromto="0.19675330240875655 0.0 0.0 0.3624719495591918 0.0 0.0" size="0.04" /><joint name="leg_6_1_knee_joint" type="hinge" axis="0 1 0" range="-90 90" damping="4.0" limited="true" /><body name="leg_6_1_foot" pos="0.3624719495591918 0.0 0.0"><geom name="leg_6_1_foot_geom" type="cylinder" fromto="0.3624719495591918 0.0 0.0 0.5379305125937245 0.0 0.0" size="0.04" /><joint name="leg_6_1_ankle_joint" type="ball" damping="6.0" /></body></body></body><body name="leg_6_2" pos="0 0.05518295701055702 0"><geom name="leg_6_2_upper_geom" type="capsule" fromto="0.0 0.0 0.0 0.1283998378649463 0.0 0.0" size="0.04" /><joint name="leg_6_2_hip_joint" type="ball" damping="2.0" /><body name="leg_6_2_lower" pos="0.1283998378649463 0.0 0.0"><geom name="leg_6_2_lower_geom" type="capsule" fromto="0.1283998378649463 0.0 0.0 0.2284103586284771 0.0 0.0" size="0.04" /><joint name="leg_6_2_knee_joint" type="hinge" axis="0 1 0" range="-90 90" damping="4.0" limited="true" /><body name="leg_6_2_foot" pos="0.2284103586284771 0.0 0.0"><geom name="leg_6_2_foot_geom" type="cylinder" fromto="0.2284103586284771 0.0 0.0 0.3305349420056378 0.0 0.0" size="0.04" /><joint name="leg_6_2_ankle_joint" type="ball" damping="6.0" /></body></body></body><body name="leg_6_3" pos="-0.1267974065989845 0 0"><geom name="leg_6_3_upper_geom" type="capsule" fromto="0.0 0.0 0.0 0.18066709357328514 0.0 0.0" size="0.04" /><joint name="leg_6_3_hip_joint" type="ball" damping="2.0" /><body name="leg_6_3_lower" pos="0.18066709357328514 0.0 0.0"><geom name="leg_6_3_lower_geom" type="capsule" fromto="0.18066709357328514 0.0 0.0 0.3772762812506942 0.0 0.0" size="0.04" /><joint name="leg_6_3_knee_joint" type="hinge" axis="0 1 0" range="-90 90" damping="4.0" limited="true" /><body name="leg_6_3_foot" pos="0.3772762812506942 0.0 0.0"><geom name="leg_6_3_foot_geom" type="cylinder" fromto="0.3772762812506942 0.0 0.0 0.5508111484189795 0.0 0.0" size="0.04" /><joint name="leg_6_3_ankle_joint" type="ball" damping="6.0" /></body></body></body></body><geom name="flag_6" type="box" size="0.05 0.05 0.5" pos="-5.603197605156326 6.057568689396138 0" material="pink" contype="1" conaffinity="7" /><body name="torso_7" pos="0 6.5 0.75"><geom name="torso_geom_torso_7" type="box" size="0.2141861989609257 0.1640992434487031 0.09672396681414343" pos="0 0 0" contype="1" conaffinity="8" material="grey" /><joint name="torso_7_root" type="free" armature="0" damping="0" limited="false" /><site name="torso_7_site" pos="0 0 0" type="sphere" size="0.01" /><body name="leg_7_1" pos="-0.10709309948046285 0 0"><geom name="leg_7_1_upper_geom" type="capsule" fromto="0.0 0.0 0.0 0.11487927407887007 0.0 0.0" size="0.04" /><joint name="leg_7_1_hip_joint" type="ball" damping="2.0" /><body name="leg_7_1_lower" pos="0.11487927407887007 0.0 0.0"><geom name="leg_7_1_lower_geom" type="capsule" fromto="0.11487927407887007 0.0 0.0 0.30321759190415154 0.0 0.0" size="0.04" /><joint name="leg_7_1_knee_joint" type="hinge" axis="0 1 0" range="-90 90" damping="4.0" limited="true" /><body name="leg_7_1_foot" pos="0.30321759190415154 0.0 0.0"><geom name="leg_7_1_foot_geom" type="cylinder" fromto="0.30321759190415154 0.0 0.0 0.4433034604644085 0.0 0.0" size="0.04" /><joint name="leg_7_1_ankle_joint" type="ball" damping="6.0" /></body></body></body><body name="leg_7_2" pos="0 0.08204962172435155 0"><geom name="leg_7_2_upper_geom" type="capsule" fromto="0.0 0.0 0.0 0.19263833338554442 0.0 0.0" size="0.04" /><joint name="leg_7_2_hip_joint" type="ball" damping="2.0" /><body name="leg_7_2_lower" pos="0.19263833338554442 0.0 0.0"><geom name="leg_7_2_lower_geom" type="capsule" fromto="0.19263833338554442 0.0 0.0 0.30973606924232855 0.0 0.0" size="0.04" /><joint name="leg_7_2_knee_joint" type="hinge" axis="0 1 0" range="-90 90" damping="4.0" limited="true" /><body name="leg_7_2_foot" pos="0.30973606924232855 0.0 0.0"><geom name="leg_7_2_foot_geom" type="cylinder" fromto="0.30973606924232855 0.0 0.0 0.48000341380119393 0.0 0.0" size="0.04" /><joint name="leg_7_2_ankle_joint" type="ball" damping="6.0" /></body></body></body><body name="leg_7_3" pos="0.10709309948046285 0 0"><geom name="leg_7_3_upper_geom" type="capsule" fromto="0.0 0.0 0.0 0.18242379500461892 0.0 0.0" size="0.04" /><joint name="leg_7_3_hip_joint" type="ball" damping="2.0" /><body name="leg_7_3_lower" pos="0.18242379500461892 0.0 0.0"><geom name="leg_7_3_lower_geom" type="capsule" fromto="0.18242379500461892 0.0 0.0 0.3328872871939757 0.0 0.0" size="0.04" /><joint name="leg_7_3_knee_joint" type="hinge" axis="0 1 0" range="-90 90" damping="4.0" limited="true" /><body name="leg_7_3_foot" pos="0.3328872871939757 0.0 0.0"><geom name="leg_7_3_foot_geom" type="cylinder" fromto="0.3328872871939757 0.0 0.0 0.5022978492867012 0.0 0.0" size="0.04" /><joint name="leg_7_3_ankle_joint" type="ball" damping="6.0" /></body></body></body><body name="leg_7_4" pos="0.10709309948046285 0 0"><geom name="leg_7_4_upper_geom" type="capsule" fromto="0.0 0.0 0.0 0.10432588479047689 0.0 0.0" size="0.04" /><joint name="leg_7_4_hip_joint" type="ball" damping="2.0" /><body name="leg_7_4_lower" pos="0.10432588479047689 0.0 0.0"><geom name="leg_7_4_lower_geom" type="capsule" fromto="0.10432588479047689 0.0 0.0 0.23774371619946405 0.0 0.0" size="0.04" /><joint name="leg_7_4_knee_joint" type="hinge" axis="0 1 0" range="-90 90" damping="4.0" limited="true" /><body name="leg_7_4_foot" pos="0.23774371619946405 0.0 0.0"><geom name="leg_7_4_foot_geom" type="cylinder" fromto="0.23774371619946405 0.0 0.0 0.40326692873227543 0.0 0.0" size="0.04" /><joint name="leg_7_4_ankle_joint" type="ball" damping="6.0" /></body></body></body></body><geom name="flag_7" type="box" size="0.05 0.05 0.5" pos="-0.6923747164958273 7.221538115387761 0" material="grey" contype="1" conaffinity="8" /><body name="torso_8" pos="6.5 6.5 0.75"><geom name="torso_geom_torso_8" type="box" size="0.24479035812401548 0.10062861518796051 0.0799959071636453" pos="0 0 0" contype="1" conaffinity="9" material="brown" /><joint name="torso_8_root" type="free" armature="0" damping="0" limited="false" /><site name="torso_8_site" pos="0 0 0" type="sphere" size="0.01" /><body name="leg_8_1" pos="0.12239517906200774 0 0"><geom name="leg_8_1_upper_geom" type="capsule" fromto="0.0 0.0 0.0 0.10251760607511255 0.0 0.0" size="0.04" /><joint name="leg_8_1_hip_joint" type="ball" damping="2.0" /><body name="leg_8_1_lower" pos="0.10251760607511255 0.0 0.0"><geom name="leg_8_1_lower_geom" type="capsule" fromto="0.10251760607511255 0.0 0.0 0.20710209658264417 0.0 0.0" size="0.04" /><joint name="leg_8_1_knee_joint" type="hinge" axis="0 1 0" range="-90 90" damping="4.0" limited="true" /><body name="leg_8_1_foot" pos="0.20710209658264417 0.0 0.0"><geom name="leg_8_1_foot_geom" type="cylinder" fromto="0.20710209658264417 0.0 0.0 0.4014355048186463 0.0 0.0" size="0.04" /><joint name="leg_8_1_ankle_joint" type="ball" damping="6.0" /></body></body></body><body name="leg_8_2" pos="0 0.050314307593980256 0"><geom name="leg_8_2_upper_geom" type="capsule" fromto="0.0 0.0 0.0 0.1379591412291172 0.0 0.0" size="0.04" /><joint name="leg_8_2_hip_joint" type="ball" damping="2.0" /><body name="leg_8_2_lower" pos="0.1379591412291172 0.0 0.0"><geom name="leg_8_2_lower_geom" type="capsule" fromto="0.1379591412291172 0.0 0.0 0.26515090650320716 0.0 0.0" size="0.04" /><joint name="leg_8_2_knee_joint" type="hinge" axis="0 1 0" range="-90 90" damping="4.0" limited="true" /><body name="leg_8_2_foot" pos="0.26515090650320716 0.0 0.0"><geom name="leg_8_2_foot_geom" type="cylinder" fromto="0.26515090650320716 0.0 0.0 0.3703770190435596 0.0 0.0" size="0.04" /><joint name="leg_8_2_ankle_joint" type="ball" damping="6.0" /></body></body></body></body><geom name="flag_8" type="box" size="0.05 0.05 0.5" pos="7.47356578766665 6.728406779857813 0" material="brown" contype="1" conaffinity="9" /><geom name="north_wall" type="box" pos="0 10.05 0.25" size="10.05 0.05 0.25" material="MatPlane" /><geom name="south_wall" type="box" pos="0 -10.05 0.25" size="10.05 0.05 0.25" material="MatPlane" /><geom name="east_wall" type="box" pos="10.05 0 0.25" size="0.05 10.05 0.25" material="MatPlane" /><geom name="west_wall" type="box" pos="-10.05 0 0.25" size="0.05 10.05 0.25" material="MatPlane" /></worldbody><actuator><motor name="leg_0_1_hip_motor" joint="leg_0_1_hip_joint" ctrllimited="true" ctrlrange="-1 1" gear="200" /><motor name="leg_0_1_ankle_joint_motor" joint="leg_0_1_ankle_joint" ctrllimited="true" ctrlrange="-1 1" gear="200" /><motor name="leg_0_2_hip_motor" joint="leg_0_2_hip_joint" ctrllimited="true" ctrlrange="-1 1" gear="200" /><motor name="leg_0_2_ankle_joint_motor" joint="leg_0_2_ankle_joint" ctrllimited="true" ctrlrange="-1 1" gear="200" /><motor name="leg_1_1_hip_motor" joint="leg_1_1_hip_joint" ctrllimited="true" ctrlrange="-1 1" gear="200" /><motor name="leg_1_1_ankle_joint_motor" joint="leg_1_1_ankle_joint" ctrllimited="true" ctrlrange="-1 1" gear="200" /><motor name="leg_2_1_hip_motor" joint="leg_2_1_hip_joint" ctrllimited="true" ctrlrange="-1 1" gear="200" /><motor name="leg_2_1_ankle_joint_motor" joint="leg_2_1_ankle_joint" ctrllimited="true" ctrlrange="-1 1" gear="200" /><motor name="leg_3_1_hip_motor" joint="leg_3_1_hip_joint" ctrllimited="true" ctrlrange="-1 1" gear="200" /><motor name="leg_3_1_ankle_joint_motor" joint="leg_3_1_ankle_joint" ctrllimited="true" ctrlrange="-1 1" gear="200" /><motor name="leg_3_2_hip_motor" joint="leg_3_2_hip_joint" ctrllimited="true" ctrlrange="-1 1" gear="200" /><motor name="leg_3_2_ankle_joint_motor" joint="leg_3_2_ankle_joint" ctrllimited="true" ctrlrange="-1 1" gear="200" /><motor name="leg_4_1_hip_motor" joint="leg_4_1_hip_joint" ctrllimited="true" ctrlrange="-1 1" gear="200" /><motor name="leg_4_1_ankle_joint_motor" joint="leg_4_1_ankle_joint" ctrllimited="true" ctrlrange="-1 1" gear="200" /><motor name="leg_4_2_hip_motor" joint="leg_4_2_hip_joint" ctrllimited="true" ctrlrange="-1 1" gear="200" /><motor name="leg_4_2_ankle_joint_motor" joint="leg_4_2_ankle_joint" ctrllimited="true" ctrlrange="-1 1" gear="200" /><motor name="leg_5_1_hip_motor" joint="leg_5_1_hip_joint" ctrllimited="true" ctrlrange="-1 1" gear="200" /><motor name="leg_5_1_ankle_joint_motor" joint="leg_5_1_ankle_joint" ctrllimited="true" ctrlrange="-1 1" gear="200" /><motor name="leg_6_1_hip_motor" joint="leg_6_1_hip_joint" ctrllimited="true" ctrlrange="-1 1" gear="200" /><motor name="leg_6_1_ankle_joint_motor" joint="leg_6_1_ankle_joint" ctrllimited="true" ctrlrange="-1 1" gear="200" /><motor name="leg_6_2_hip_motor" joint="leg_6_2_hip_joint" ctrllimited="true" ctrlrange="-1 1" gear="200" /><motor name="leg_6_2_ankle_joint_motor" joint="leg_6_2_ankle_joint" ctrllimited="true" ctrlrange="-1 1" gear="200" /><motor name="leg_6_3_hip_motor" joint="leg_6_3_hip_joint" ctrllimited="true" ctrlrange="-1 1" gear="200" /><motor name="leg_6_3_ankle_joint_motor" joint="leg_6_3_ankle_joint" ctrllimited="true" ctrlrange="-1 1" gear="200" /><motor name="leg_7_1_hip_motor" joint="leg_7_1_hip_joint" ctrllimited="true" ctrlrange="-1 1" gear="200" /><motor name="leg_7_1_ankle_joint_motor" joint="leg_7_1_ankle_joint" ctrllimited="true" ctrlrange="-1 1" gear="200" /><motor name="leg_7_2_hip_motor" joint="leg_7_2_hip_joint" ctrllimited="true" ctrlrange="-1 1" gear="200" /><motor name="leg_7_2_ankle_joint_motor" joint="leg_7_2_ankle_joint" ctrllimited="true" ctrlrange="-1 1" gear="200" /><motor name="leg_7_3_hip_motor" joint="leg_7_3_hip_joint" ctrllimited="true" ctrlrange="-1 1" gear="200" /><motor name="leg_7_3_ankle_joint_motor" joint="leg_7_3_ankle_joint" ctrllimited="true" ctrlrange="-1 1" gear="200" /><motor name="leg_7_4_hip_motor" joint="leg_7_4_hip_joint" ctrllimited="true" ctrlrange="-1 1" gear="200" /><motor name="leg_7_4_ankle_joint_motor" joint="leg_7_4_ankle_joint" ctrllimited="true" ctrlrange="-1 1" gear="200" /><motor name="leg_8_1_hip_motor" joint="leg_8_1_hip_joint" ctrllimited="true" ctrlrange="-1 1" gear="200" /><motor name="leg_8_1_ankle_joint_motor" joint="leg_8_1_ankle_joint" ctrllimited="true" ctrlrange="-1 1" gear="200" /><motor name="leg_8_2_hip_motor" joint="leg_8_2_hip_joint" ctrllimited="true" ctrlrange="-1 1" gear="200" /><motor name="leg_8_2_ankle_joint_motor" joint="leg_8_2_ankle_joint" ctrllimited="true" ctrlrange="-1 1" gear="200" /></actuator><sensor><accelerometer name="torso_0_accel" site="torso_0_site" /><gyro name="torso_0_gyro" site="torso_0_site" /><accelerometer name="torso_1_accel" site="torso_1_site" /><gyro name="torso_1_gyro" site="torso_1_site" /><accelerometer name="torso_2_accel" site="torso_2_site" /><gyro name="torso_2_gyro" site="torso_2_site" /><accelerometer name="torso_3_accel" site="torso_3_site" /><gyro name="torso_3_gyro" site="torso_3_site" /><accelerometer name="torso_4_accel" site="torso_4_site" /><gyro name="torso_4_gyro" site="torso_4_site" /><accelerometer name="torso_5_accel" site="torso_5_site" /><gyro name="torso_5_gyro" site="torso_5_site" /><accelerometer name="torso_6_accel" site="torso_6_site" /><gyro name="torso_6_gyro" site="torso_6_site" /><accelerometer name="torso_7_accel" site="torso_7_site" /><gyro name="torso_7_gyro" site="torso_7_site" /><accelerometer name="torso_8_accel" site="torso_8_site" /><gyro name="torso_8_gyro" site="torso_8_site" /></sensor></mujoco>